<p>アサーション・メソッドが "<code translate="no">java.lang.AssertionError</code>" を投げています。この呼び出しが、同様のエラーをキャッチするtry-catchのtryブロック内で行われる場合、例外のいくつかのプロパティをテストすることを確認する必要があります。そうでなければ、アサーションは決して失敗しません。</p>
<h2>コンプライアンス違反のコード例</h2>
<pre translate="no">
@Test
public void should_throw_assertion_error() {
  try {
    throwAssertionError();
    Assert.fail("Expected an AssertionError!"); // Noncompliant, the AssertionError will be caught and the test will never fail.
  } catch (AssertionError e) {}
}

private void throwAssertionError() {
  throw new AssertionError("My assertion error");
}
</pre>
<h2>コンプライアンス・ソリューション</h2>
<pre translate="no">
assertThrows(AssertionError.class, () -&gt; throwAssertionError());
</pre>
<pre translate="no">
try {
   throwAssertionError();
   Assert.fail("Expected an AssertionError!"); // Compliant, we made sure to test that the correct error is raised
 } catch (AssertionError e) {
   Assert.assertThat(e.getMessage(), is("My assertion error"));
 }
</pre>
<h2>見る</h2>
<ul>
  <li><a href="https://github.com/junit-team/junit4/wiki/Exception-testing">JUnit 4の例外テストに関するドキュメント</a></li>
</ul>

